Workbook
Name L_CATEGORIAS: _LISTAS!$D$4:$D$12
Name L_CERTEZA: _LISTAS!$L$4:$L$6
Name L_DIRECCION: _LISTAS!$P$4:$P$6
Name L_ESTADO: _LISTAS!$E$4:$E$6
Name L_FUNCION: _LISTAS!$J$4:$J$12
Name L_HOJAS: _LISTAS!$A$4:$A$15
Name L_NIVEL_REL: _LISTAS!$O$4:$O$6
Name L_OBLIGATORIO: _LISTAS!$C$4:$C$6
Name L_PAIS: _LISTAS!$I$4:$I$15
Name L_SEGMENTO: _LISTAS!$K$4:$K$12
Name L_SPN: _LISTAS!$R$4:$R$6
Name L_TIER: _LISTAS!$H$4:$H$6
Name L_TIPO_ACTOR: _LISTAS!$M$4:$M$36
Name L_TIPO_CAMBIO: _LISTAS!$F$4:$F$14
Name L_TIPO_RELACION: _LISTAS!$N$4:$N$12
Name L_TIPOS_DATO: _LISTAS!$B$4:$B$9
Name L_VERTICAL: _LISTAS!$G$4:$G$12
Name L_VIS_POI: _LISTAS!$Q$4:$Q$6

Sheet DASHBOARD
A2: Mapa del Ecosistema Deportivo Mexicano 2026 | I2: v1.00.31
A3: PANEL EJECUTIVO · Vista de navegación rápida del workbook | I3: Playbook Sports Intelligence · Confidencial
A5: Panorama del universo
A6: 110 | D6: 114 | G6: 263 | J6: 159
A7: ACTORES ACTIVOS | D7: TIER 1 + TIER 2 | G7: RELACIONES | J7: POIS
A8: 149 totales · 2 desactivados | D8: 51 Tier 1 · 63 Tier 2 | G8: en Mapa de Conexiones
A10: 9 | D10: 33 | G10: 22 | J10: 7
A11: VERTICALES | D11: SUBCAPACIDADES | G11: REGLAS VIGENTES | J11: Clusters de poder
D12: en matriz Amplitud Funcional
A14: Navegar por vertical
A15: Cada vertical abre su ficha detallada. Click en el número con flecha para navegar.
A16: V1 | B16: Rights Owners | D16: 51 → | E16: V2 | F16: Media & Distribution | H16: 23 → | I16: V3 | J16: Commercialization | L16: 29 →
A17: Quien controla los derechos primarios de una competición o evento serial | E17: Quien empaqueta y distribuye contenido deportivo | I17: Sponsors y marcas que monetizan el deporte
A19: V4 | B19: Agencies & Talent | D19: 16 → | E19: V5 | F19: Events & Experiences | H19: 24 → | I19: V6 | J19: Ticketing & Access | L19: 19 →
A20: Agencias de representación, marketing deportivo, hospitality B2B | E20: Operadores de eventos masivos y experiencias deportivas | I20: Plataformas de boleteo primario y Fan ID
A22: V7 | B22: Infrastructure | D22: 27 → | E22: V8 | F22: Sports Tech & Data | H22: 18 → | I22: V9 | J22: Capital & Investment | L22: 22 →
A23: Venues, estadios, arenas con valor estratégico | E23: Tecnología B2B aplicada al deporte: data, analytics, SaaS | I23: Capital deportivo: PE, family offices, fondos
A26: Top 15 actores · Score Compuesto
A27: Combinación 50/50 de Amplitud (presencia cross-vertical) y Profundidad (densidad por vertical activa). Tier 1 resaltado en ámbar.
A28: # | B28: Actor | G28: Tier | H28: Vert. | I28: Tipo Capacidad | K28: Ampl. | L28: Comp.
A29: 1 | B29: A-035 Endeavor / WME Group | G29: T1 | H29: V9 | I29: Multi-cap. | K29: 9 | L29: 0.781
A30: 2 | B30: A-044 FEMSA / Club de Fútbol Monterrey Rayados | G30: T1 | H30: V9 | I30: Multi-cap. | K30: 9 | L30: 0.781
A31: 3 | B31: A-020 CIE / OCESA (V5 Experiencias) | G31: T1 | H31: V5 | I31: Multi-cap. | K31: 7.5 | L31: 0.729
A32: 4 | B32: A-043 Federación Mexicana de Fútbol | G32: T1 | H32: V1 | I32: Especialista | K32: 4 | L32: 0.722
A33: 5 | B33: A-084 Liga MX | G33: T1 | H33: V1 | I33: Especialista | K33: 4 | L33: 0.722
A34: 6 | B34: A-104 Octagon | G34: T2 | H34: V4 | I34: Especialista | K34: 4 | L34: 0.722
A35: 7 | B35: A-059 Grupo Martí / Familia Harp Helú | G35: T1 | H35: V9 | I35: Multi-cap. | K35: 7.5 | L35: 0.651
A36: 8 | B36: A-025 Consejo Mundial de Lucha Libre (CMLL) | G36: T2 | H36: V1 | I36: Especialista | K36: 5.5 | L36: 0.649
A37: 9 | B37: A-083 Liga Mexicana del Pacífico (LMP) | G37: T2 | H37: V1 | I37: Especialista | K37: 5.5 | L37: 0.649
A38: 10 | B38: A-151 Liga BBVA MX Femenil | G38: T1 | H38: V1 | I38: Especialista | K38: 3.5 | L38: 0.632
A39: 11 | B39: A-071 HG Promotores en Deporte y Entretenimiento | G39: T3 | H39: V5 | I39: Especialista | K39: 5 | L39: 0.59
A40: 12 | B40: A-085 LIV Golf League (Mexico City) | G40: T2 | H40: V1 | I40: Especialista | K40: 5 | L40: 0.59
... A43: 15 | B43: A-105 Ollamani, S.A.B. / Grupo Águilas (Club América + Estadi | G43: T1 | H43: V9 | I43: Multi-cap. | K43: 6 | L43: 0.583
A44: → Ranking completo de los 151 actores en hoja AMPLITUD FUNCIONAL
A46: Índice del workbook
A47: Acceso directo a cada hoja del libro con descripción de qué contiene.
A48: Hoja | E48: Contenido | J48: Tipo
A49: UNIVERSO MAESTRO | E49: Catálogo principal de 151 actores con ficha completa | J49: Master · 23 columnas por actor
A50: AMPLITUD FUNCIONAL | E50: Matriz 151 × 33 subcaps con scores Vx, Amplitud, Profundidad y Compuesto | J50: Scoring
A51: MAPA DE CONEXIONES | E51: 263 relaciones tipo A→B (Sponsorship, Inst., Data, Rights, Venue, Ticketing) | J51: Relaciones
...

Sheet PIEDRAS ANGULARES
B3: PIEDRAS ANGULARES
B4: Los 10 mandamientos del Mapa
B5: Por qué hacemos esto y qué NO somos. Esto antecede a las 22 reglas metodológicas: las reglas operativas se derivan de aquí.
B8: 01 | C8: Un mapa, no un censo | E8: R-08, S-01, S-02
C9: Incluimos lo que mueve la aguja, no todo lo que existe.
C10: El universo no es exhaustivo. Cada actor cargado tiene que justificar su lugar con señal estratégica diferenciada. Si quitarlo no cambia la lectura del ecosistema, no entra.
B12: 02 | C12: Estructural sobre opinático | E12: M-AF-01 a M-AF-19
C13: Cada actor se evalúa por lo que hace, no por lo que dice que hace.
C14: Las subcapacidades de Amplitud Funcional son binarias, no impresiones. Si un sponsor dice "tenemos activación 360" pero solo paga jersey, no califica activación 360. La evidencia manda sobre el comunicado oficial.
B16: 03 | C16: Capacidad operativa, no facturación | E16: AMPLITUD FUNCIONAL completa
C17: El score mide qué puede hacer un actor, no cuánto factura ni cuánto vale.
C18: No es un ranking financiero. Endeavor y FEMSA empatan en Score Compuesto (0.781) aunque sus revenues son muy distintos. La pregunta del score es: "¿qué cosas puede ejecutar este actor en el ecosistema?", no "¿cuánto dinero mueve?".
B20: 04 | C20: Una sola línea de propiedad | E20: R-01, R-12, R-13, M-AF-01
C21: Si el padre está mapeado, el hijo se hereda. No duplicamos.
C22: Cuando un club, equipo o activo es 100% propiedad de un holding mapeado, no se carga como actor standalone. Su capacidad se hereda al padre y su identidad se preserva en Productos/Propiedades y Notas. Esto evita un universo inflado (Rayados no aparece 3 veces: como club, como FEMSA, como Estadio BBVA).
B24: 05 | C24: Doble eje obligatorio | E24: AMPLITUD FUNCIONAL · cols Amplitud, Profundidad, Compuesto
C25: Amplitud y Profundidad valen lo mismo. Ni holdings diversificados ni especialistas verticales dominan solos.
C26: Sin Profundidad, los holdings arrasan cualquier ranking y los especialistas desaparecen. Octagon (Especialista V4) y Endeavor (Diversificado) tienen Score Compuesto similar porque ambos perfiles son relevantes para el cliente. El doble eje es la decisión metodológica más fundamental del scoring.
B28: 06 | C28: Las relaciones tienen dirección | E28: M-01, REL-01 a REL-03
C29: A→B describe quién hace qué a quién. No son grafos simétricos por default.
C30: En Sponsorship, A es la marca y B la propiedad esponsoreada. En Ownership, A es el padre y B el hijo. En Rights/Media, A es el rights holder y B el broadcaster. La direccionalidad cambia la lectura: invertirla puede cambiar el sentido del cluster. Solo las membresías simétricas (JVs) usan A↔B.
B32: 07 | C32: Trazabilidad sobre conclusión | E32: CHANGELOG · REGLAS METODOLÓGICAS · campo Fuente en MC
C33: Cada celda se justifica. Cada cambio queda en CHANGELOG.
C34: No hay celda sin fuente. No hay decisión sin regla detrás. No hay versión sin entrada en CHANGELOG. Esto permite que el sistema sobreviva al autor: se puede persona puede entrar en 6 meses y reconstruir por qué cada decisión es como es.
B36: 08 | C36: El mapa es un sistema vivo | E36: CHANGELOG · campo Notas de propiedad
C37: Cada versión es snapshot, no verdad eterna. La validez depende de la fecha.
C38: En 2025-2026 el ecosistema cambió más que en los 10 años anteriores: General Atlantic entró a Ollamani, Apollo cerró Atlético Madrid, 4 clubes Liga MX cambiaron de dueño, Wasserman se rebrandeó a THE·TEAM. Un mapa "para siempre" sería un mapa falso. La versión vigente al cierre de v1.00.30 es la verdad del 11 de mayo de 2026, no la del próximo trimestre.
B40: 09 | C40: Verificación antes de elegancia | E40: campo Certeza · M-AF-19
C41: Una fuente única es flag amarillo, no celda lista.
C42: El campo Certeza distingue Verificado (2+ fuentes), Fuente única (pendiente cross-check) y Desactivado. Una afirmación no sustituye verificación. Si no podemos contrastar, lo decimos: "Fuente única".
B44: 10 | C44: Inteligencia accionable, no decoración | E44: Toda la arquitectura del workbook
C45: Cada deliverable existe porque cambia una decisión.
C46: Ningún slide, gráfico, hoja o ficha se construye "porque queda bien". Cada elemento del workbook tiene un sentido y valor agreagado.
B51: Las 22 reglas metodológicas de operación se derivan de estos 10 principios. Si una regla nueva contradice un mandamiento, el mandamiento gana. Si dos mandamientos parecen contradecirse, gana el de menor número.

Sheet DICCIONARIO
A1: ◼ PLAYBOOK | B1: DICCIONARIO DE CAMPOS
A2: Playbook Sports Intelligence | B2: Lista canónica de campos del workbook · Una sola fuente de verdad por concepto
A3: Playbook_Mapeo_v1.00.xlsx · Mapa del Ecosistema Deportivo Mexicano 2026 · CONFIDENCIAL · Uso interno
A5: Campo | B5: Hoja origen | C5: Tipo de dato | D5: Valores permitidos | E5: Obligatorio | F5: Descripción | G5: Criterio de asignación | H5: Notas
A6: ↓ Catálogo completo de campos del workbook. Una sola fuente de verdad por concepto. Para cualquier conflicto entre hojas, este diccionario prevalece.
A7: ID | B7: UNIVERSO MAESTRO | C7: Texto | D7: A-001 a A-XXX (4 dígitos) | E7: Sí | F7: Identificador único e inmutable del actor en el workbook. | G7: Asignación secuencial al cargar. Una vez asignado NO se reutiliza si el actor se desactiva. | H7: Convención: A- prefijo + 3 dígitos. Inmutable.
A8: ID Vertical | B8: UNIVERSO MAESTRO | C8: Texto | D8: V1-001 a V9-XXX | E8: Sí | F8: Identificador secundario del actor en su vertical primaria. | G8: Asignado en el orden de carga dentro de la vertical primaria. | H8: Permite cruce rápido con FICHAS_Vx. Inmutable.
A9: Nombre | B9: UNIVERSO MAESTRO | C9: Texto | D9: — | E9: Sí | F9: Nombre canónico del actor como aparece en comunicaciones oficiales. | G9: Usar el nombre legal o el más conocido públicamente. Para holdings: nombre del holding + activo principal entre paréntesis. | H9: Ejemplo: Ollamani, S.A.B. / Grupo Águilas (Club América + Estadio Banorte)
A10: Vertical Primaria | B10: UNIVERSO MAESTRO | C10: Lista | D10: V1, V2, V3, V4, V5, V6, V7, V8, V9 | E10: Sí | F10: Vertical funcional principal donde el actor concentra su actividad operativa. | G10: Regla T-01: la vertical donde tiene mayor Score (puntajes 1.0 / 0.5 / 0) en las subcaps de esa vertical. Empate: la primera por orden V1→V9. | H10: Solo UNA. Las demás presencias se documentan vía Etiquetas Secundarias.
A11: Etiquetas Secundarias | B11: UNIVERSO MAESTRO | C11: Lista (multi) | D11: V1, V2, V3, V4, V5, V6, V7, V8, V9 | E11: No | F11: Verticales adicionales donde el actor tiene presencia operativa (Score ≥ 0.5). | G11: Auto-derivable de AMPLITUD FUNCIONAL. Se documenta para visibilidad rápida sin abrir AF. | H11: Separadas por coma. Ejemplo: V5, V7
A12: Tipo | B12: UNIVERSO MAESTRO | C12: Lista | D12: L_TIPO_ACTOR (33 valores) | E12: Sí | F12: Categoría operativa del actor (Holding, Club, Liga, Sponsor, Federación, etc). | G12: Asignación por naturaleza primaria del actor. | H12: Ver _LISTAS columna M para catálogo completo.
A13: Tier | B13: UNIVERSO MAESTRO | C13: Lista | D13: Tier 1, Tier 2, Tier 3 | E13: Sí | F13: Nivel de relevancia estratégica del actor en el ecosistema. | G13: Tier 1: actor dominante en su vertical / Tier 2: actor relevante con escala / Tier 3: actor menor con señal estratégica diferenciada (regla R-08). | H13: 51 Tier 1, 63 Tier 2, resto Tier 3.
A14: País | B14: UNIVERSO MAESTRO | C14: Lista | D14: México, USA, España, Brasil, etc. | E14: Sí | F14: País de origen del HQ corporativo del actor. | G14: Para multinacionales: país del HQ global, no de la oficina MX. | H14: Apollo Sports Capital = USA (aunque opera ASL en MX).
A15: Ciudad | B15: UNIVERSO MAESTRO | C15: Texto | D15: — | E15: No | F15: Ciudad del HQ operativo en México (cuando aplica). | G15: Para multinacionales sin oficina MX: dejar vacío.
A16: Rol | B16: UNIVERSO MAESTRO | C16: Texto | D16: — | E16: No | F16: Síntesis de una línea de qué hace el actor. | G16: Empezar con verbo de acción (opera, produce, distribuye, monetiza, regula...). Max 100 chars. | H16: Se usa en Overview de fichas y dashboards.
A17: Sector | B17: UNIVERSO MAESTRO | C17: Texto | D17: — | E17: No | F17: Sector de mercado donde opera el actor. | G17: Usar nomenclatura GICS o equivalente: Sports Media, Consumer Brands, Financial Services, Private Equity, etc. | H17: Diferenciar Sector (Consumer Brands) de Tipo (Sponsor).
A18: Descripción | B18: UNIVERSO MAESTRO | C18: Texto largo | D18: — | E18: Sí | F18: Párrafo de 2-4 líneas explicando qué hace el actor, su escala y su relevancia para el ecosistema MX. | G18: Información factual verificable. Sin opiniones ni adjetivos sin sustento. Cerrar con dato de escala (USD, % market share, # de propiedades, etc.) cuando se tenga. | H18: Es la primera fuente para el Overview de fichas.
A19: Por qué importa | B19: UNIVERSO MAESTRO | C19: Texto largo | D19: — | E19: No | F19: Síntesis de relevancia estratégica: ¿qué pasaría si este actor desapareciera mañana? | G19: Pensar en el contrafáctico. Si hay sustitutos directos en el ecosistema MX, el actor es menos crítico. | H19: Útil para priorización en deliverables al cliente.
A20: Productos / Propiedades | B20: UNIVERSO MAESTRO | C20: Texto largo | D20: — | E20: Sí | F20: Lista de propiedades distintivas, productos o subsidiarias del actor. | G20: Separar con · (middle dot). Incluir naming sponsors, eventos seriales, venues operados, marcas controladas. Para holdings: incluir club varonil + femenil cuando aplique (R-13). | H20: Es el campo más usado en el Dashboard y FICHAS.
A21: Estructura corporativa | B21: UNIVERSO MAESTRO | C21: Texto | D21: — | E21: No | F21: Forma legal del actor: S.A.B., S.A. de C.V., LLC, Foundation, Family Office, etc. | G21: Tomar del registro mercantil o documento corporativo público.
A22: Notas de propiedad | B22: UNIVERSO MAESTRO | C22: Texto largo | D22: — | E22: No | F22: Notas sobre estructura de ownership, cambios accionarios recientes, controlling shareholders. | G22: Cuando aplica regla R-12/R-13: incluir marker explícito ej. [R-13: Propiedad cross-género...]. Cuando hay venta en proceso: marcar [VENTA EN PROCESO] con fecha esperada de cierre. | H22: Campo crítico para tracking de cambios estructurales 2025-2026.
A23: Web | B23: UNIVERSO MAESTRO | C23: URL | D23: — | E23: No | F23: Sitio web oficial del actor. | G23: URL completa con https://. Usar dominio corporativo no marketing.
A24: Certeza | B24: UNIVERSO MAESTRO | C24: Lista | D24: Verificado, Fuente única, Desactivado | E24: Sí | F24: Nivel de validación de la información del actor. | G24: Verificado: dos fuentes mínimo. Fuente única: información de un solo origen, marcar para validar. Desactivado: actor removido del scope pero mantenido para trazabilidad. | H24: En v1.00.29: 2 actores Desactivados (Hard Rock Stadium, CAA Sports MX).
A25: Visualizable | B25: UNIVERSO MAESTRO | C25: Lista | D25: Sí, No | E25: Sí | F25: Si el actor se incluye en visualizaciones (bubble map, network) y dashboards. | G25: No: para actores Desactivados o que se mantienen para trazabilidad histórica sin querer comunicarlos. | H25: 110 visualizables de 151 totales.
A26: Score V1 a V9 | B26: AMPLITUD FUNCIONAL | C26: Numérico | D26: 0 a 4 (suma de subcaps) | E26: Calc | F26: Promedio de las subcapacidades de cada vertical para el actor. | G26: Cada vertical tiene 3-6 subcaps. Suma de scores 1.0/0.5/0 dividido entre número de subcaps activas. | H26: Calculado automáticamente desde la matriz 151×33.
A27: Amplitud | B27: AMPLITUD FUNCIONAL | C27: Numérico | D27: 0 a 9 | E27: Calc | F27: Suma simple de los 9 scores Vx. | G27: Cuanto más alto, mayor presencia cross-vertical. | H27: Holdings diversificados dominan este score.
A28: Profundidad | B28: AMPLITUD FUNCIONAL | C28: Numérico | D28: 0 a 1 | E28: Calc | F28: Amplitud dividida entre número de verticales con presencia > 0. | G28: Cuanto más alto, mayor concentración funcional en pocas verticales. | H28: Especialistas dominan este score.
A29: Compuesto | B29: AMPLITUD FUNCIONAL | C29: Numérico | D29: 0 a 1 | E29: Calc | F29: Combinación normalizada 50/50 de Amplitud y Profundidad contra el max observado. | G29: Es el score de referencia para rankings. Balancea ancho y profundidad. | H29: Top: Endeavor 0.781, FEMSA 0.781, OCESA 0.729.
A30: Tipo Capacidad | B30: AMPLITUD FUNCIONAL | C30: Calc | D30: Especialista / Multi-capacidad / Diversificado | E30: Calc | F30: Categoría auto-derivada por número de verticales con presencia (Score Vx ≥ 1). | G30: Especialista: 1-2 verticales. Multi-capacidad: 3-4. Diversificado: 5+. | H30: En v1.00.29: 129 Especialistas, 16 Multi-capacidad, 0 Diversificado.
A31: ID Relación | B31: MAPA DE CONEXIONES | C31: Texto | D31: R-001 a R-XXX | E31: Sí | F31: Identificador único e inmutable de la relación. | G31: Asignación secuencial al cargar. No reutilizable si la relación se elimina.
A32: Actor A | B32: MAPA DE CONEXIONES | C32: Texto | D32: ID de UM | E32: Sí | F32: Identificador del actor del lado activo de la relación. | G32: Regla M-01: dirección A→B donde A es el agente, B el receptor. | H32: Sponsorship A=marca, B=propiedad esponsoreada. Ownership A=padre, B=hijo.
A33: Actor B | B33: MAPA DE CONEXIONES | C33: Texto | D33: ID de UM | E33: Sí | F33: Identificador del actor del lado receptor. | G33: Ver M-01.
A34: Tipo de relación | B34: MAPA DE CONEXIONES | C34: Lista | D34: L_TIPO_RELACION (8 valores) | E34: Sí | F34: Tipo canónico: Sponsorship, Institutional/Regulatory, Rights/Media, Venue/Operations, Ticketing/Access, Agency/Intermediation, Ownership/Control, Data/Fan Intelligence, Strategic/Operational. | G34: Asignación según naturaleza primaria de la relación. Si hay dos tipos: crear dos relaciones separadas. | H34: Top 3 en v1.00.30: Sponsorship 71, Inst./Reg 39, Data/Fan 29.
A35: Nivel | B35: MAPA DE CONEXIONES | C35: Lista | D35: R1, R2, R3 | E35: Sí | F35: Nivel de validación / certeza de la relación. | G35: R1: dos fuentes mínimo + relación pública. R2: una fuente confiable o relación pública pero no documentada en detalle. R3: inferida lógicamente, pendiente verificación.
A36: Dirección | B36: MAPA DE CONEXIONES | C36: Lista | D36: A→B, A↔B | E36: Sí | F36: Direccionalidad de la relación. | G36: A→B: una dirección clara. A↔B: bidireccional simétrica (raro, solo en JVs o membresías).
A37: Descripción | B37: MAPA DE CONEXIONES | C37: Texto largo | D37: — | E37: Sí | F37: Qué es exactamente la relación: contrato, alianza, propiedad, etc. | G37: Empezar con sustantivo concreto. Incluir cifra (USD, %, fechas) cuando exista.
A38: Por qué importa | B38: MAPA DE CONEXIONES | C38: Texto largo | D38: — | E38: No | F38: Relevancia estratégica de la relación. | G38: Pensar en el contrafáctico: ¿qué cambia si la relación se rompe?
A39: Fuente | B39: MAPA DE CONEXIONES | C39: Texto | D39: — | E39: No | F39: Referencias bibliográficas, URLs o documentos de respaldo. | G39: Comunicados oficiales, prensa especializada (ESPN, Sportico, Forbes), filings (BMV, SEC).
A40: ID POI | B40: POI MAESTRO | C40: Texto | D40: P-001 a P-XXX | E40: Sí | F40: Identificador único de la persona física. | G40: Asignación secuencial. Inmutable.
A41: Actor asociado | B41: POI MAESTRO | C41: Texto | D41: ID de UM | E41: Sí | F41: Actor al que está vinculado el POI. | G41: Si el POI está vinculado a 2+ actores, crear entradas separadas o documentar en Notas.
...

Sheet UNIVERSO MAESTRO
A1: ◼ PLAYBOOK | B1: UNIVERSO MAESTRO
A2: Playbook Sports Intelligence | B2: Base de datos canónica de actores · Una fila por actor activo · Fuente de verdad del workbook
A3: Playbook_Mapeo_v1.00.xlsx · Mapa del Ecosistema Deportivo Mexicano 2026 · CONFIDENCIAL · Uso interno
A5: ID Maestro | B5: ID Vertical | C5: Nombre del actor | D5: Vertical primaria | E5: Etiquetas secundarias | F5: Tipo de actor | G5: Tier | H5: País de origen | I5: Ciudad / base operativa MX | J5: Función comercial principal | K5: Segmento deportivo prioritario | L5: Qué hace realmente | M5: Por qué importa | N5: Known For | O5: Productos / propiedades | P5: Notas de propiedad | Q5: Sitio web | R5: Nivel de certeza | S5: Flag / Fuentes | T5: Visualizable en mapa ejecutivo
A6: A-016 | B6: V1-001 | C6: Canelo Promotions / Saúl Álvarez | D6: V1 | E6: V4 · V3 | F6: Promoción / Boxing promotion | G6: Tier 1 | H6: México | I6: San Diego, CA / Guadalajara | J6: Controla propiedad / capital | K6: Boxeo | L6: El atleta individual de mayor valor comercial de México. DAZN como broadcaster exclusivo. Hennessy, Tecate, Michelob Ultra y Oakley como sponsors principales. GGG vs Canelo generó más de USD 160M en PPV en EE.UU. | M6: Canelo es el activo deportivo individual más valioso de México. Su modelo de gestión 360° (Reynoso como manager-entrenador-promotor) es único en el boxeo mundial. Los ingresos por pelea superan el revenue anual de muchos clubes Liga MX. | N6: Canelo Promotions (boxeo) · Canelo Espectáculos · Canelo Store (retail) · Canelo Technologies (app I Can) · Canelo Energy (4 gasolineras Jalisco) · Upper (80 tiendas conveniencia) · SSA Inmobiliaria · SSA Capitales · VMC Drinks (tequila) · Yaoca (rehidratante) · CA (residuos/agua) · Línea autobuses Jalisco · Taquería El Pastor del Rica | O6: Canelo Media · No Boxing No Life · Saúl "Canelo" Álvarez (atleta franquicia) | P6: Vehículo comercial de Saúl Álvarez. Producción de contenido (Canelo Media), promoción de peleas (No Boxing No Life), gestión de derechos del atleta. [v1.00.29: conglomerado ampliado a 12+ empresas según ESPN/Forbes/El Heraldo. Promotora propia desde 2021 tras separación Golden Boy. Fortuna estimada USD 275M Forbes 2025.] | Q6: canelo.tv | R6: Verificado | T6: =IF(G6="","",IF(OR(G6="Tier 3"),"No",IF(AND(S6<>"",OR(ISNUMBER(SEARCH("OFAC",S6)),ISNUMBER(SEARCH("penal",S6)),ISNUMBER(SEARCH("rojo pendiente",S6)))),"Revisar","Sí"))) -> Sí
A7: A-017 | B7: V1-002 | C7: Capitanes de Ciudad de México (NBA G-League) | D7: V1 | E7: V7 · V9 | F7: Club basketball / NBA G-League | G7: Tier 2 | H7: México | I7: CDMX | L7: Compite en NBA G-League. Único equipo NBA-affiliated en LATAM. | M7: Plataforma para introducir baloncesto NBA-grade en MX. Operación Arena CDMX (sub-arrendamiento). | N7: Capitanes de Ciudad de México (NBA G-League) · Arena Ciudad de México (home games) · Programa Capitanes Academy · Affiliate de Oklahoma City Thunder (NBA) | P7: [v1.00.29: única franquicia G-League fuera EE.UU./Canadá. Filial NBA G-League directamente operada por NBA Properties; juega en Arena CDMX (Avalanz A-056).] | Q7: capitanescdmx.com | R7: Verificado | T7: =IF(G7="","",IF(OR(G7="Tier 3"),"No",IF(AND(S7<>"",OR(ISNUMBER(SEARCH("OFAC",S7)),ISNUMBER(SEARCH("penal",S7)),ISNUMBER(SEARCH("rojo pendiente",S7)))),"Revisar","Sí"))) -> Sí
A8: A-019 | B8: V1-003 | C8: Charros de Jalisco (LMB + LMP) | D8: V1 | E8: V7 | F8: Club LMB / Béisbol profesional | G8: Tier 2 | H8: México | I8: Guadalajara | K8: Béisbol | L8: Doble franquicia LMB verano y LMP invierno. Sede Estadio Panamericano (Zapopan). | M8: Charros Jalisco: única franquicia con doble temporada activa. Campeón LMP 2018-19. Mercado GDL. | N8: Charros de Jalisco beisbol varonil (LMB Banorte verano + LMP invierno) · Charros de Jalisco Femenil softbol (LMS) · Estadio Panamericano (Zapopan) · Academia formativa | P8: [v1.00.29: doble temporada LMB (verano) + LMP (invierno). Campeón LMS 2024 (softbol femenil). Sociedad familia Salcido.] | Q8: charrosbeisbol.com | R8: Verificado | T8: =IF(G8="","",IF(OR(G8="Tier 3"),"No",IF(AND(S8<>"",OR(ISNUMBER(SEARCH("OFAC",S8)),ISNUMBER(SEARCH("penal",S8)),ISNUMBER(SEARCH("rojo pendiente",S8)))),"Revisar","Sí"))) -> Sí
A9: A-021 | B9: V1-004 | C9: Club Necaxa | D9: V1 | E9: V3 · V7 | F9: Club Liga MX | G9: Tier 3 | H9: México | I9: Aguascalientes | J9: Controla propiedad / capital | K9: Fútbol | L9: Club con modelo de ownership mixto que incluye celebridades del deporte norteamericano como accionistas. Broadcaster: Claro Sports (compartido). Segunda Spectrum (Genius Sports) como proveedor de tracking de jugadores. | M9: Primer club Liga MX con tracking de jugadores de nivel NBA. Accionistas celebrity del deporte norteamericano. Presencia en el radar del mercado norteamericano. | N9: Accionistas celebrity norteamericanos; Segunda Spectrum (first tracking Liga MX de nivel NBA) · Necaxa Femenil | P9: [R-13: Propiedad cross-género: el equipo femenil se mapea como propiedad dentro de este actor, no como actor standalone separado.] | Q9: necaxa.com | R9: Verificado | T9: sí
A10: A-022 | B10: V1-005 | C10: Club Toluca | D10: V1 | E10: V3 · V7 | F10: Club Liga MX | G10: Tier 1 | H10: México | I10: Toluca, Estado de México | J10: Controla propiedad / capital | K10: Fútbol | L10: BICAMPEÓN 2025: Clausura 2025 (11° título, rompió sequía 15 años) y Apertura 2025 (12° título, vs Tigres en penales 9-8). Empata a Chivas como segundo club más ganador de Liga MX. | M10: Bicampeón Liga MX 2025 bajo DT Turco Mohamed. Primer DT extranjero con 4 títulos en 4 equipos distintos de Liga MX. Campeones Cup 2025 vs LA Galaxy. Paulinho como fichaje más caro de su historia. | N10: Toluca FC (varonil + Diablas Femenil) · Estadio Nemesio Diez (La Bombonera) · Academia AGA Toluca · Sede WC26 secundaria (entrenamientos selecciones) | P10: [R-13: Propiedad cross-género: el equipo femenil se mapea como propiedad dentro de este actor, no como actor standalone separado.] [v1.00.29: bicampeón Liga MX 2023 + 2024. Operación bajo familia Martínez-Cinta; vínculo histórico con familia Harp Helú (A-059).] | Q10: toluca.com.mx | R10: Verificado | T10: =IF(G10="","",IF(OR(G10="Tier 3"),"No",IF(AND(S10<>"",OR(ISNUMBER(SEARCH("OFAC",S10)),ISNUMBER(SEARCH("penal",S10)),ISNUMBER(SEARCH("rojo pendiente",S10)))),"Revisar","Sí"))) -> Sí
A11: A-025 | B11: V1-006 | C11: Consejo Mundial de Lucha Libre (CMLL) | D11: V1 | E11: V7 | F11: Lucha libre / Wrestling promotion | G11: Tier 2 | H11: México | I11: CDMX + Guadalajara | L11: Lucha libre tradicional, viernes y domingos en Arena México. Empresa más antigua del mundo en su giro. | M11: Cathedral de la lucha libre. Doble venue propio (Arena México + Arena Coliseo GDL). Sin TKO ownership: independiente. | N11: Función Sábado Arena México · Función Domingo Arena Coliseo · Arena Puebla (martes) · Arena Coliseo Guadalajara · Anniversary Show · Sin Salida · Homenaje a Dos Leyendas · Juicio Final · Cuadrilateral CMLL · Reality Estrellas del Ring | O11: Arena México · Arena Coliseo (CDMX) · Arena Puebla · Programación weekly Viernes Espectacular | P11: Federación de lucha libre profesional más antigua del mundo (1933). Opera 3 arenas propias y programación weekly. Distinta de AAA (que está consolidada en Endeavor). [v1.00.29: empresa familiar Roldán desde 1933. Liga propia, opera 4 arenas. Alianza con New Japan Pro Wrestling.] | Q11: cmll.com | R11: Verificado | T11: =IF(G12="","",IF(OR(G12="Tier 3"),"No",IF(AND(S12<>"",OR(ISNUMBER(SEARCH("OFAC",S12)),ISNUMBER(SEARCH("penal",S12)),ISNUMBER(SEARCH("rojo pendiente",S12)))),"Revisar","Sí"))) -> Sí
A12: A-026 | B12: V1-007 | C12: Consejo Municipal del Deporte de Guadalajara (COMUDE GDL) | D12: V1 | E12: V5 · V6 | F12: Institución pública deportiva | G12: Tier 1 | H12: México | I12: Guadalajara, Jalisco | J12: Controla propiedad / capital | K12: Running / Wellness | L12: Rights holder y presidente del comité organizador del Medio Maratón Internacional Guadalajara Electrolit (XL edición 2026: 23,000 participantes, WA Platinum Label, Patrimonio Cultural Inmaterial de Guadalajara) y del Maratón Internacional Guadalajara Skarch (XLI edición 2025: 4,000 participantes). Equivalente funcional al INDEPORTE para la Ciudad de México pero en el ámbito municipal de Guadalajara. | M12: Gatekeeper institucional de los dos eventos de running con mayor convocatoria de Guadalajara. El Medio Maratón GDL Electrolit con WA Platinum Label y 23,000 participantes es más relevante técnicamente que el Maratón CDMX (WA Gold Label). | N12: Rights holder Medio Maratón Internacional Guadalajara Electrolit (WA Platinum Label, Patrimonio Cultural Inmaterial, 23,000 participantes); rights holder Maratón Internacional Guadalajara Skarch | R12: Verificado | T12: =IF(G13="","",IF(OR(G13="Tier 3"),"No",IF(AND(S13<>"",OR(ISNUMBER(SEARCH("OFAC",S13)),ISNUMBER(SEARCH("penal",S13)),ISNUMBER(SEARCH("rojo pendiente",S13)))),"Revisar","Sí"))) -> Sí
A13: A-027 | B13: V1-008 | C13: Copa Mundial FIFA 2026 en México | D13: V1 | E13: V7 · V5 | F13: Evento / Torneo con derechos propios | G13: Tier 1 | H13: Suiza | I13: Ciudad de México / Guadalajara / Monterrey | J13: Controla propiedad / capital | K13: Eventos premium | L13: El evento deportivo más monetizado de la historia celebrado en México. 13 partidos en tres sedes (Banorte-CDMX: 5, Akron-GDL: 4, BBVA-MTY: 4). El partido inaugural (11 jun-2026) enfrenta a México vs Sudáfrica en el Estadio Banorte con 83,000 espectadores. FIFA controla todos los ingresos directos de hospitalidad, ticketing y derechos globales. | M13: Genera la mayor derrama económica de evento deportivo en la historia de México. Restructura todo el ecosistema de sponsors, ticketing, medios y venues durante may-jul 2026. Cataliza USD 3,866M+ en inversión en infraestructura deportiva. | N13: 13 partidos en MX; partido inaugural México vs Sudáfrica (Banorte, 11 jun-2026); USD 3,866M+ inversión infraestructura | Q13: fifa.com/worldcup | R13: Verificado | T13: =IF(G14="","",IF(OR(G14="Tier 3"),"No",IF(AND(S14<>"",OR(ISNUMBER(SEARCH("OFAC",S14)),ISNUMBER(SEARCH("penal",S14)),ISNUMBER(SEARCH("rojo pendiente",S14)))),"Revisar","Sí"))) -> Sí
A14: A-029 | B14: V1-009 | C14: Cruz Azul FC | D14: V1 | E14: V3 · V7 | F14: Club Liga MX | G14: Tier 2 | H14: México | I14: Ciudad de México | J14: Controla propiedad / capital | K14: Fútbol | L14: Modelo de sociedad cooperativa sin dueño único — el único en Liga MX. Busca estadio propio a largo plazo. | M14: Modelo de ownership cooperativo único en Liga MX (sin dueño persona física o empresa). | N14: Sociedad cooperativa única Liga MX · Cruz Azul Femenil (Estadio Centenario Cuernavaca local Clausura 2026) | P14: [R-13: Propiedad cross-género: el equipo femenil se mapea como propiedad dentro de este actor, no como actor standalone separado.] | Q14: cruzazul.com.mx | R14: Verificado | T14: sí
A15: A-043 | B15: V1-010 | C15: Federación Mexicana de Fútbol | D15: V1 | E15: V4 · V3 | F15: Federación deportiva | G15: Tier 1 | H15: México | I15: Ciudad de México | J15: Controla propiedad / capital | K15: Fútbol | L15: Organiza a las selecciones nacionales mexicanas (varonil, femenil, sub-23, sub-20, futsal). Negocia y otorga derechos de transmisión de partidos de la Selección. Certifica árbitros, clubes y competiciones. Opera el CITEC para tecnología deportiva. Comisionado: Mikel Arriola. | M15: Rights holder de la Selección Mexicana de Fútbol, el activo deportivo con mayor valor de patrocinio en México. Sus contratos (Adidas USD 290M/10 años, AT&T telecom exclusivo, Amazon triple deal, TEAM Marketing derechos globales, Netflix Concacaf) definen el piso del ecosistema comercial. | N15: Rights holder El Tri; Adidas USD 290M/10 años hasta 2034; TEAM Marketing derechos globales 2026-34; Genius Sports SAOT | Q15: fmf.mx | R15: Verificado | T15: =IF(G16="","",IF(OR(G16="Tier 3"),"No",IF(AND(S16<>"",OR(ISNUMBER(SEARCH("OFAC",S16)),ISNUMBER(SEARCH("penal",S16)),ISNUMBER(SEARCH("rojo pendiente",S16)))),"Revisar","Sí"))) -> Sí
A16: A-052 | B16: V1-011 | C16: Global Champions Tour — LGCT México | D16: V1 | E16: V3 · V5 | F16: Evento / Torneo con derechos propios | G16: Tier 2 | H16: Otros | I16: Ciudad de México | J16: Controla propiedad / capital | K16: Eventos premium | L16: Organiza la etapa México del Global Champions Tour y la Global Champions League en el Estadio GNP Seguros, CDMX. GNP Seguros como presenting partner desde 2023. Francisco Pasquel/Oxer Sports como promotor local. Contrato extendido hasta 2033. | M16: El único evento ecuestre de élite en México y uno de los más rentables del circuito. La extensión hasta 2033 fue motivada en parte por la llegada de la Premier Jumping League (anunciada mar-abr 2026, inicio 2027) al mercado. | N16: LGCT contrato extendido hasta 2033; GNP Seguros presenting; único ecuestre élite en México | Q16: globalchampionsseries.com | R16: Verificado | T16: =IF(G18="","",IF(OR(G18="Tier 3"),"No",IF(AND(S18<>"",OR(ISNUMBER(SEARCH("OFAC",S18)),ISNUMBER(SEARCH("penal",S18)),ISNUMBER(SEARCH("rojo pendiente",S18)))),"Revisar","Sí"))) -> Sí
A17: A-055 | B17: V1-012 | C17: Gran Premio de México — Fórmula 1 | D17: V1 | E17: V4 · V3 | F17: Evento / Torneo con derechos propios | G17: Tier 1 | H17: Reino Unido | I17: Ciudad de México (Autódromo Hermanos Rodríguez) | J17: Controla propiedad / capital | K17: Motorsport | L17: Contrato extendido abr-2025 para 2026-2028. Fideicomiso privado de ~100 empresas paga fee F1 a Liberty Media (~USD 40-45M/año). Récord 2024: 404,958 asistentes en el fin de semana. Derrama estimada 2025: MXN 20,892M. Costo operativo: ~USD 72M/año. | M17: Evento deportivo más monetizado del país. El único en el mundo con fideicomiso privado multi-empresa para financiar el fee del rights holder. Formula One Group retiene todos los derechos globales de transmisión y hospitality (vía F1 Experiences). | N17: Derrama MXN 137,000M acumulada 2015-2024; récord 404,958 asistentes 2024; fideicomiso privado ~100 empresas | Q17: formula1.com | R17: Verificado | T17: sí
A18: A-075 | B18: V1-013 | C18: INDEPORTE — Instituto del Deporte de la Ciudad de México | D18: V1 | E18: V5 · V6 | F18: Institución pública deportiva | G18: Tier 1 | H18: México | I18: Ciudad de México (Av. División del Norte 2333) | J18: Controla propiedad / capital | K18: Running / Wellness | L18: Rights holder institucional y presidente del comité organizador del Maratón CDMX Telcel (XLIII edición 2026, WA Gold Label, ~30,000 inscritos) y del Medio Maratón CDMX BBVA (XIX edición 2026, AIMS certificado, ~30,000 inscritos). Opera las plataformas de registro oficial (maraton.cdmx.gob.mx y 21k.cdmx.gob.mx). Negocia y otorga los naming rights de los eventos a sponsors. | M18: Controla el inventario comercial de los dos eventos de running más convocados de México: 60,000+ registros combinados. La negociación de title sponsorship (BBVA, Telcel) pasa por INDEPORTE como rights holder. | N18: Rights holder Maratón CDMX Telcel (WA Gold Label); rights holder Medio Maratón CDMX BBVA; plataformas oficiales 21k.cdmx.gob.mx y maraton.cdmx.gob.mx | Q18: indeporte.cdmx.gob.mx | R18: Verificado | T18: =IF(G20="","",IF(OR(G20="Tier 3"),"No",IF(AND(S20<>"",OR(ISNUMBER(SEARCH("OFAC",S20)),ISNUMBER(SEARCH("penal",S20)),ISNUMBER(SEARCH("rojo pendiente",S20)))),"Revisar","Sí"))) -> Sí
A19: A-083 | B19: V1-014 | C19: Liga Mexicana del Pacífico (LMP) | D19: V1 | E19: V2 | F19: Club LMB / Béisbol profesional | G19: Tier 2 | H19: México | I19: Sede LMP (Hermosillo) | K19: Béisbol | L19: Organiza temporada béisbol invernal oct-feb. Campeón clasifica a Serie del Caribe. | M19: Una de las 2 ligas pro de béisbol en MX (junto con LMB verano). Plataforma para Serie del Caribe (representa MX). | N19: LMP temporada invierno (octubre-enero) · Caribbean Series (con Cuba, RD, PR, VEN, Colombia, Panamá) · 10 clubes (Charros, Tomateros, Naranjeros, Yaquis, Águilas, Sultanes Pacífico, Mayos, Cañeros, Venados, Jaiberos) · Acuerdo televisivo ESPN Latin America | P19: [v1.00.29: liga premier de invierno LATAM. Representa MX en Serie del Caribe MLB Pathway. CEO Omar Canizales.] | Q19: lmp.mx | R19: Verificado | T19: =IF(G21="","",IF(OR(G21="Tier 3"),"No",IF(AND(S21<>"",OR(ISNUMBER(SEARCH("OFAC",S21)),ISNUMBER(SEARCH("penal",S21)),ISNUMBER(SEARCH("rojo pendiente",S21)))),"Revisar","Sí"))) -> Sí
A20: A-084 | B20: V1-015 | C20: Liga MX | D20: V1 | E20: V9 · V4 | F20: Evento / Torneo con derechos propios | G20: Tier 1 | H20: México | I20: Ciudad de México | J20: Controla propiedad / capital | K20: Fútbol | L20: Organiza el torneo de fútbol profesional más importante de México. Desde abr-2026 aprobó modelo de gobernanza como AC independiente (23-abr-2026); constitución jurídica formal proyectada para julio 2026 — a mayo-2026 NO está formalmente constituida. Modelo: Premier League / LaLiga. 4 comités estratégicos: Deportivo, Comercial, Inversión, Certificación y Ética. | M20: La separación jurídica FMF-Liga MX es el evento de gobernanza más importante en décadas. Abre ventana real a centralización comercial valorada en USD 480M+ anuales. Gestiona los contratos con BBVA (title), Caliente.mx (casa de apuestas oficial), Genius Sports (datos) y TEAM Marketing (derechos globales selecciones). | N20: Liga BBVA MX varonil (Apertura/Clausura) · Liga MX Femenil (A-151 vía R-06) · Campeón de Campeones · Leagues Cup (con MLS) · eLiga MX (esports oficial) · Liga de Expansión MX (Ascenso suspendido) · Asamblea de Dueños | P20: [v1.00.29: presidente Mikel Arriola. Proceso 2026 de eliminación multipropiedad: Atlas, Querétaro, Mazatlán, León vendidos. Asamblea aprobó llegada Atlante (Escalante).] | Q20: ligamx.net | R20: Verificado | S20: Separación jurídica FMF-Liga MX abr-2026; candidatura Iturbide a presidente (Fuente única) | FECHA CORREGIDA: la asamblea fue el 23-abr-2026 (Asamblea Ordinaria de Dueños, Toluca), no '23-24'. Votación unánime de los 18 clubes confirmada por Reforma, Infobae, El Universal, ESPN. | T20: Sí
A21: A-085 | B21: V1-016 | C21: LIV Golf League (Mexico City) | D21: V1 | E21: V9 · V5 | F21: Evento / Torneo con derechos propios | G21: Tier 2 | H21: Arabia Saudita | I21: Ciudad de México (sede) | J21: Controla propiedad / capital | K21: Eventos premium | L21: Liga premium de golf disruptiva financiada por PIF (Saudi Public Investment Fund). Etapa Mexico City se juega anualmente en el Club de Golf Chapultepec. Primera edición MX 2023, recurrente desde entonces. Modelo de torneo con team play + individual play + premio prize $25M USD por evento. | M21: Único evento premium internacional V1 cuyo control de capital pasa directamente por PIF (V9-021). Su presencia en MX vincula el ecosistema deportivo mexicano con capital soberano saudí. Sede CDMX la convierte en stop premium de golf global cuando PGA Tour MX se juega en Vidanta Vallarta. | N21: LIV Golf México City (Club de Golf Chapultepec) · Anual ene-feb · Etapa LIV Tour Global · Patrocinio HSBC, Aramco, Riyadh Air | P21: Sede operativa Club de Golf Chapultepec; controlado 100% por PIF [v1.00.29: rebautizada en 2024-25 como LIV Golf México (de Mayakoba a Chapultepec). Backers Public Investment Fund Saudi Arabia.] | Q21: livgolf.com | R21: Verificado | T21: =IF(G23="","",IF(OR(G23="Tier 3"),"No",IF(AND(S23<>"",OR(ISNUMBER(SEARCH("OFAC",S23)),ISNUMBER(SEARCH("penal",S23)),ISNUMBER(SEARCH("rojo pendiente",S23)))),"Revisar","Sí"))) -> Sí
A22: A-087 | B22: V1-017 | C22: Maratón de la Ciudad de México Telcel | D22: V1 | E22: V6 | F22: Evento / Torneo con derechos propios | G22: Tier 1 | H22: México | I22: Ciudad de México (salida: CU/UNAM; meta: Zócalo) | J22: Controla audiencia | K22: Running / Wellness | L22: Organiza el maratón de 42K más grande de México por inscritos (~30,000) y el único con etiqueta WA Gold Label en el país. Edición 2026 (XLIII): 30 de agosto, salida desde Insurgentes/CU, meta en el Zócalo. Incluye serial preparatorio de carreras coordinado por INDEPORTE. | M22: Único WA Gold Label de México. Mayor evento de running por masa crítica: 30,000 corredores activos. Telcel lleva más de 10 años como title sponsor. | N22: Único WA Gold Label México; XLIII edición 2026 (30 ago); ~30,000 inscritos; Telcel title sponsor 10+ años; salida CU, meta Zócalo | O22: Maratón anual CDMX (42K) · Eventos satélite (medio maratón, 10K) | P22: Evento operado por INDEPORTE Ciudad de México con title sponsor Telcel. Producción ejecutiva: Emoción Deportiva. | Q22: maraton.cdmx.gob.mx | R22: Verificado | T22: sí
A23: A-088 | B23: V1-018 | C23: Maratón Powerade Monterrey | D23: V1 | E23: V6 | F23: Evento / Torneo con derechos propios | G23: Tier 2 | H23: México | I23: Monterrey, Nuevo León (Parque Fundidora, salida y meta) | J23: Controla audiencia | K23: Running / Wellness | L23: Organiza el segundo maratón de México por número de participantes (8,300 en edición 2025). 42K, certificado AIMS, clasificatorio Boston, aval FMAA e IAAF. 19 ediciones. Title sponsor: Powerade (vía Coca-Cola V3-025). Presentado con Brooks Running México. Operado por comité privado independiente. | M23: El segundo maratón de México por participación. A diferencia del Maratón CDMX (propiedad pública) y el Medio Maratón GDL (propiedad municipal), el Maratón Powerade Monterrey es propiedad de un comité privado: el modelo de acceso para sponsors es distinto. | N23: Segundo maratón de México por participantes (8,300 en 2025); 19 ediciones; AIMS clasificatorio Boston; Powerade title sponsor vía Coca-Cola; Brooks Running México presenting | O23: Maratón Monterrey 42K (anual) | P23: Title sponsor Powerade (The Coca-Cola Company). Operación local Asociación de Atletismo de Nuevo León. | Q23: maratonmonterrey.mx | R23: Verificado | T23: sí
A24: A-092 | B24: V1-019 | C24: Medio Maratón de la Ciudad de México BBVA | D24: V1 | E24: V6 | F24: Evento / Torneo con derechos propios | G24: Tier 1 | H24: México | I24: Ciudad de México (ruta nueva 2026: salida Hemiciclo a Juárez; meta Ángel de la Independencia) | J24: Controla audiencia | K24: Running / Wellness | L24: Organiza el medio maratón de 21K más grande de México por inscritos (~30,000), con certificación AIMS y avales de la FMAA y World Athletics. Expo de 3 días en WTC CDMX (100,000 visitantes en 2025). Edición 2026: XIX, julio 2026. Estrena ruta nueva. | M24: 30,000 corredores inscritos y Expo con 100,000 visitantes convierten al evento en el mayor punto de contacto de marca en running de CDMX por densidad de interacción. BBVA documentado como title sponsor en la ficha V3-001 del tracker. | N24: XIX edición 2026 con ruta nueva; Expo 100,000 visitantes WTC CDMX; BBVA title sponsor; ~30,000 inscritos; AIMS certificado | O24: Medio Maratón CDMX 21K (anual) · Eventos satélite | P24: Title sponsor BBVA. Operación INDEPORTE CDMX. Producción Emoción Deportiva. | Q24: 21k.cdmx.gob.mx | R24: Verificado | T24: sí
A25: A-093 | B25: V1-020 | C25: Medio Maratón Internacional Guadalajara Electrolit | D25: V1 | E25: V6 | F25: Evento / Torneo con derechos propios | G25: Tier 1 | H25: México | I25: Guadalajara, Jalisco (meta: Zona Minerva) | J25: Controla audiencia | K25: Running / Wellness | L25: Organiza el mayor evento de running de Guadalajara: 23,000 participantes (cupo ampliado, inscripciones agotadas en dic-2025), WA Platinum Label (máxima certificación WA, superior al Gold Label del Maratón CDMX), clasificatorio para Campeonato Mundial de Medio Maratón. Patrimonio Cultural Inmaterial del Municipio de Guadalajara. 40 ediciones consecutivas. | M25: El evento de running con mayor certificación técnica de México (Platinum Label vs Gold Label del Maratón CDMX). Electrolit construyó su dominio en el segmento de bebidas deportivas en parte a través del naming de este evento. | N25: WA Platinum Label (único en México); 23,000 participantes, cupo agotado en dic-2025; 40 ediciones; Electrolit title sponsor; Patrimonio Cultural Inmaterial Guadalajara | O25: Medio Maratón GDL 21K (anual) · Eventos satélite | P25: Title sponsor Electrolit (Grupo PiSA). Operación local Comude Guadalajara. | R25: Verificado | S25: | Confirmado: este evento es el referido en correcciones como "21K Guadalajara". Mismo evento, nomenclatura consolidada en "Medio Maratón Internacional Guadalajara Electrolit". | T25: sí
A26: A-098 | B26: V1-021 | C26: Naranjeros de Hermosillo (LMP) | D26: V1 | E26: V7 | F26: Club LMB / Béisbol profesional | G26: Tier 3 | H26: México | I26: Hermosillo | K26: Béisbol | L26: Compite en LMP invernal. Sede Estadio Sonora. | M26: Naranjeros: plurihistórico Serie del Caribe. Tradición LMP Sonora. | N26: Estadio Sonora; Serie del Caribe múltiples | Q26: naranjeros.com.mx | R26: Verificado | T26: =IF(G28="","",IF(OR(G28="Tier 3"),"No",IF(AND(S28<>"",OR(ISNUMBER(SEARCH("OFAC",S28)),ISNUMBER(SEARCH("penal",S28)),ISNUMBER(SEARCH("rojo pendiente",S28)))),"Revisar","Sí"))) -> Sí
A27: A-102 | B27: V1-022 | C27: NFL México City Games | D27: V1 | E27: V3 · V7 | F27: Evento / Torneo con derechos propios | G27: Tier 2 | H27: EUA | I27: Ciudad de México (Estadio Banorte) | J27: Controla propiedad / capital | K27: Eventos premium | L27: Organiza partidos de temporada regular de la NFL en el Estadio Banorte. El acuerdo 2026-2028 confirma al Banorte como venue NFL para tres temporadas consecutivas con los 49ers como equipo local. NFL México City Games 2026 será el primer partido de la NFL en el Estadio Banorte reabierto. | M27: El evento internacional con mayor valor de patrocinio por edición después del GP México. La estructura 2026-2028 con los 49ers ancla al Banorte como venue internacional de primer nivel y valida la inversión de Ollamani/General Atlantic. | N27: Acuerdo 2026-2028 Estadio Banorte con 49ers; Banorte presenting partner NFL México; primer NFL en Banorte reabierto | Q27: nfl.com/international | R27: Verificado | T27: =IF(G30="","",IF(OR(G30="Tier 3"),"No",IF(AND(S30<>"",OR(ISNUMBER(SEARCH("OFAC",S30)),ISNUMBER(SEARCH("penal",S30)),ISNUMBER(SEARCH("rojo pendiente",S30)))),"Revisar","Sí"))) -> Sí
A28: A-115 | B28: V1-023 | C28: Pumas UNAM | D28: V1 | E28: V3 · V7 | F28: Club Liga MX | G28: Tier 2 | H28: México | I28: Ciudad de México | J28: Controla propiedad / capital | K28: Fútbol | L28: Su identidad y base de fans CDMX son su principal activo comercial. | M28: Único club Liga MX de propiedad pública universitaria. Base de fans universitaria en la capital. | N28: Propiedad UNAM; Estadio Olímpico Universitario patrimonio UNESCO; identidad universitaria única · Pumas UNAM Femenil | P28: [R-13: Propiedad cross-género: el equipo femenil se mapea como propiedad dentro de este actor, no como actor standalone separado.] | Q28: pumasfútbol.mx | R28: Verificado | T28: =IF(G33="","",IF(OR(G33="Tier 3"),"No",IF(AND(S33<>"",OR(ISNUMBER(SEARCH("OFAC",S33)),ISNUMBER(SEARCH("penal",S33)),ISNUMBER(SEARCH("rojo pendiente",S33)))),"Revisar","Sí"))) -> No
A29: A-123 | B29: V1-024 | C29: Selección Mexicana de Fútbol | D29: V1 | E29: V7 · V3 | F29: Selección nacional | G29: Tier 1 | H29: México | I29: Ciudad de México | J29: Controla propiedad / capital | K29: Fútbol | L29: Compite internacionalmente en FIFA, CONCACAF y eventos de preparación. Genera el mayor volumen de audiencia puntual del ecosistema deportivo mexicano. Sus partidos de clasificación mundialista, amistosos y participaciones en Copa Oro y Copa América son el producto con mayor demanda de patrocinio del mercado. | M29: La SNM es el activo de mayor concentración de patrocinios en un solo producto deportivo de México: Adidas (kit USD 290M/10 años), AT&T (telecom exclusivo), Amazon (triple deal mar-2025), Caliente.mx (oct-2025), Maggi/Nestlé, Uber/Uber Eats, Coca-Cola. Co-anfitrión WC26: sede inaugural en Estadio Banorte (partido México-Sudáfrica, 11 jun-2026). | N29: Selección Mexicana Mayor varonil (El Tri) · Selecciones juveniles Sub-15/Sub-17/Sub-20/Sub-23 · Tour por EE.UU. via SUM (6 fuegos/año hasta 2028) · Patrocinio adidas kit (extensión hasta 2034) · Sede WC26 país anfitrión (Banorte, BBVA, Akron + Coliseo GNP Zapopan) | P29: [v1.00.29: bajo FMF (A-043). DT Javier Aguirre. Selección juega 3-de-cada-4 partidos en EE.UU. desde 2023 vía contrato SUM hasta 2028.] | Q29: fmf.mx | R29: Verificado | T29: =IF(G34="","",IF(OR(G34="Tier 3"),"No",IF(AND(S34<>"",OR(ISNUMBER(SEARCH("OFAC",S34)),ISNUMBER(SEARCH("penal",S34)),ISNUMBER(SEARCH("rojo pendiente",S34)))),"Revisar","Sí"))) -> No
A30: A-124 | B30: V1-025 | C30: Selección Mexicana Femenil | D30: V1 | E30: V3 · V4 | F30: Selección nacional | G30: Tier 2 | H30: México | I30: Ciudad de México | J30: Controla propiedad / capital | K30: Fútbol | L30: Genera el inventario comercial del segmento femenil del ecosistema deportivo mexicano junto con la Liga MX Femenil. Amazon, AT&T y Scotiabank firmaron acuerdos específicos de patrocinio femenil. | M30: Activo con crecimiento acelerado de patrocinios femeniles. El triple deal Amazon incluye Liga MX Femenil. Scotiabank pivotó a ecosistema femenil Concacaf + Chivas fuerzas básicas. Primera Sub-20 femenil clasificada a Mundial Sub-20 en dos ediciones. | N30: Triple deal Amazon (Tri + Liga MX + Liga MX Femenil); Scotiabank pivot femenil; crecimiento acelerado patrocinios | Q30: fmf.mx | R30: Verificado | T30: =IF(G35="","",IF(OR(G35="Tier 3"),"No",IF(AND(S35<>"",OR(ISNUMBER(SEARCH("OFAC",S35)),ISNUMBER(SEARCH("penal",S35)),ISNUMBER(SEARCH("rojo pendiente",S35)))),"Revisar","Sí"))) -> Sí
A31: A-133 | B31: V1-026 | C31: Sultanes de Monterrey (LMB) | D31: V1 | E31: V7 | F31: Club LMB / Béisbol profesional | G31: Tier 2 | H31: México | I31: Monterrey | K31: Béisbol | L31: Compite en LMB. Sede Estadio Monterrey con naming Walmart desde 2024. | M31: Sultanes: institución LMB norte. Único naming Walmart en deporte profesional MX. | N31: Sultanes Monterrey LMB Banorte (varonil verano) · Sultanes Monterrey Softball (LMS femenil) · Estadio Mobil Super (Palacio Sultán) · Academia formativa · Calendario 87 ediciones LMB | O31: Walmart Park | P31: 1 propiedades absorbidas. Control operativo verificado en auditoría Padres/Hijos v3. Walmart Park: dueño legal Walmart México, operación Sultanes vía concesión. [v1.00.29: doble franquicia LMB beisbol + LMS softball. Estadio renombrado Mobil Super (ex Walmart Park). Bajo familia Maíz / Grupo Pesa.] | Q31: sultanes.com.mx | R31: Verificado | T31: sí
A32: A-138 | B32: V1-027 | C32: Tomateros de Culiacán (LMP) | D32: V1 | E32: V7 | F32: Club LMB / Béisbol profesional | G32: Tier 3 | H32: México | I32: Culiacán | K32: Béisbol | L32: Compite en LMP invernal. Sede Estadio Tomateros. | M32: Tomateros: equipo más popular invernal Sinaloa. Campeón LMP recurrente. | N32: Estadio Tomateros; campeones LMP múltiples | Q32: tomaterosdeculiacan.com | R32: Verificado | T32: =IF(G38="","",IF(OR(G38="Tier 3"),"No",IF(AND(S38<>"",OR(ISNUMBER(SEARCH("OFAC",S38)),ISNUMBER(SEARCH("penal",S38)),ISNUMBER(SEARCH("rojo pendiente",S38)))),"Revisar","Sí"))) -> Sí
A33: A-139 | B33: V1-028 | C33: Toros de Tijuana (LMB) | D33: V1 | E33: V7 · V3 | F33: Club LMB / Béisbol profesional | G33: Tier 3 | H33: México | I33: Tijuana | K33: Béisbol | L33: Compite en LMB. Sede Estadio Chevron (naming desde 2018). | M33: Toros Tijuana: única franquicia LMB frontera norte. Naming Chevron. | N33: Estadio Chevron desde 2018 | Q33: torosdetijuana.com | R33: Verificado | T33: =IF(G39="","",IF(OR(G39="Tier 3"),"No",IF(AND(S39<>"",OR(ISNUMBER(SEARCH("OFAC",S39)),ISNUMBER(SEARCH("penal",S39)),ISNUMBER(SEARCH("rojo pendiente",S39)))),"Revisar","Sí"))) -> Sí
A34: A-141 | B34: V1-029 | C34: Venados de Mazatlán (LMP) | D34: V1 | E34: V7 | F34: Club LMB / Béisbol profesional | G34: Tier 3 | H34: México | I34: Mazatlán | K34: Béisbol | L34: Compite en LMP invernal. Sede Estadio Teodoro Mariscal. | M34: Venados: plurihistórico Serie del Caribe. Tradición LMP Sinaloa. | N34: Serie del Caribe múltiples; Estadio Teodoro Mariscal | Q34: venados.com.mx | R34: Verificado | T34: =IF(G40="","",IF(OR(G40="Tier 3"),"No",IF(AND(S40<>"",OR(ISNUMBER(SEARCH("OFAC",S40)),ISNUMBER(SEARCH("penal",S40)),ISNUMBER(SEARCH("rojo pendiente",S40)))),"Revisar","Sí"))) -> Sí
A35: A-143 | B35: V1-030 | C35: Victum Sports México (HYROX México) | D35: V1 | E35: V5 | F35: Evento / Torneo con derechos propios | G35: Tier 2 | H35: México | I35: Ciudad de México (Santa Fe) | J35: Controla propiedad / capital | K35: Running / Wellness | L35: Organiza y opera la serie de eventos HYROX en México bajo licencia exclusiva de HYROX World GmbH (Hamburgo). Temporada 2025/2026: 6 eventos en 6 ciudades (CDMX, GDL, MTY, Acapulco, Cancún, Puebla). Gestiona la relación con gimnasios gym partner locales. 152,000 seguidores en Instagram (@hyroxmx). Licencia exclusiva M: Victum es rights holder mexicano por contrato con HYROX World GmbH. | M35: HYROX es el formato de fitness competitivo de mayor crecimiento global post-2020. Victum llevó HYROX a México de la misma forma que lo hizo en España: primero licencia exclusiva, luego escalado de eventos. Smart Fit como naming partner de toda la temporada. | N35: Licenciatario exclusivo HYROX en México (y previamente Iberia); 6 eventos/temporada en 6 ciudades; Smart Fit como naming partner temporada 25/26; fundadores Álvaro Taracena y Jan Peters; RFC: VSM240815SP6 | O35: HYROX México | P35: 1 propiedades absorbidas. Control operativo verificado en auditoría Padres/Hijos v3. | Q35: hyrox.mx | R35: Verificado | T35: =IF(G41="","",IF(OR(G41="Tier 3"),"No",IF(AND(S41<>"",OR(ISNUMBER(SEARCH("OFAC",S41)),ISNUMBER(SEARCH("penal",S41)),ISNUMBER(SEARCH("rojo pendiente",S41)))),"Revisar","Sí"))) -> No
A36: A-147 | B36: V1-031 | C36: World Boxing Council (WBC) — sede CDMX | D36: V1 | F36: Federación deportiva | G36: Tier 2 | H36: México | I36: CDMX (sede) | K36: Boxeo | L36: Sancionar peleas y rankings boxeo profesional mundial. Otorga cinturón verde WBC. | M36: Una de las 4 federaciones principales mundo (WBC, WBA, IBF, WBO). Sede CDMX desde 1963. Mauricio Sulaimán presidente. | N36: World Boxing Council titulación · Convention anual · Diploma y cinturón verde-oro · Rankings mundiales · WBC Cares (fundación) · WBC Muay Thai · WBC MMA · sede oficial Ciudad de México | O36: Sanción peleas título WBC · Convenciones anuales · Programa Clean Boxing | P36: Organismo regulador internacional de boxeo, sede en CDMX. Mauricio Sulaimán presidente. Sanciona ~70% de peleas profesionales globales. [v1.00.29: presidente Mauricio Sulaimán Saldívar. Único de los 4 sancionadores con sede MX (vs WBA/IBF/WBO).] | Q36: wbcboxing.com | R36: Verificado | T36: =IF(G42="","",IF(OR(G42="Tier 3"),"No",IF(AND(S42<>"",OR(ISNUMBER(SEARCH("OFAC",S42)),ISNUMBER(SEARCH("penal",S42)),ISNUMBER(SEARCH("rojo pendiente",S42)))),"Revisar","Sí"))) -> Sí
A37: A-150 | B37: V1-032 | C37: Kings League Mexico (ex Kings League Americas) / Kings League Openbank Mexico | D37: V1 | E37: V2 · V6 | F37: Evento / Torneo con derechos propios | G37: Tier 2 | H37: España (Kosmos / Gerard Piqué) | I37: Ciudad de México (Cupra Arena, MX) + Estadio BBVA (Final Four 2025) | J37: Produce y comercializa torneo | K37: Fútbol 7 / Esports / Creator economy | L37: Liga de fútbol 7-vs-7 fundada por Gerard Piqué en 2022. Edición Americas / Mexico debutó ene-2024 con 12 equipos presididos por streamers y futbolistas (Miguel Layún presidente). Sponsors confirmados: Santander/Openbank (title), Bimbo, Sportium, McDonalds, Adidas. Broadcasters MX: Twitch, YouTube, Televisa, ESPN/Disney+. Final Four 2025 en Estadio BBVA (Porcinos FC campeón). Para 2026 DAZN compró rights globales solo en mercados específicos (Spain, Italy, Germany domestic), no MX directamente. | M37: Modelo creator-led + digital-first sin precedente en MX: bypass del ecosistema Liga MX clásico, captación de audiencia joven via Twitch/YouTube. Caso de uso para Gustavo en V6 (whitelabel ticketing, vínculo FANKI a verificar) y V2 (modelo digital-first sin TV tradicional dominante). | N37: Kings League Americas (rebrand Mexico 2025) · Openbank/Santander title · Piqué/Kosmos founder · Layún Pres. MX · Final Four BBVA Monterrey | O37: Liga propia (rights holder) | P37: Holding global Kosmos Sports & Gerard Piqué. Operación local con licenciatarios y sponsors regionales. CEO global Kings League: Djamel Agaoua. Presidente liga MX/Americas: Miguel Layún. | Q37: kingsleague.pro/en/americas | R37: Verificado | T37: Sí
A38: A-151 | B38: V1-033 | C38: Liga BBVA MX Femenil | D38: V1 | E38: V2 | F38: Federación deportiva | G38: Tier 1 | H38: México | I38: Ciudad de México | J38: Empaqueta competición | K38: Fútbol femenil | L38: Liga MX Femenil (oficialmente Liga BBVA MX Femenil) fundada en 2017, asociación de miembros con 18 clubes que reflejan la estructura de la Liga MX varonil. Aplica regla R-06/E-02 (membresía constitutiva, no absorción) y R-13 (clubes femeniles como propiedades dentro de holdings existentes). En el workbook 17 de 18 clubes femeniles se cubren vía herencia desde el holding o club varonil padre ya mapeado; FC Juárez Bravas se excluye bajo E-07 (huérfano sin contraparte varonil mapeada, propietario Grupo Multimedios no figura en UM). Naming sponsor BBVA. Régimen de derechos centralizado vs Liga MX varonil (caso por revisar bajo M-AF-05). En contexto Mundial Femenino 2027 co-anfitrión MX-USA, el activo crece en relevancia. | M38: Activo en alza pre-Mundial Femenino 2027 (MX co-anfitrión confirmado). Régimen de derechos televisivos y comerciales tiene espacio para centralización (decisión Asamblea pendiente). Caso V1 con potencial de crecimiento en visibilidad para todos los holdings padres ya mapeados. | N38: Liga BBVA MX Femenil · 17 clubes-miembros cubiertos vía herencia de holdings (R-13) · FC Juárez Bravas excluida (E-07) · Sponsor titular BBVA · Mundial Femenino 2027 catalizador | O38: Asociación de miembros (no holding, regla R-06) | P38: Asociación de miembros bajo el paraguas de FMF y Liga MX AC. Los 18 clubes son miembros (no hijos consolidados). Aplica R-06 (membresía no absorción), E-02 (excepción Liga MX vs clubes), R-13 (propiedades cross-género en holdings) y E-07 (exclusión femeniles huérfanos). 17 de 18 clubes mapeados vía herencia de actores padre existentes. | Q38: ligamxfemenil.net | R38: Verificado | T38: Sí
A39: A-004 | B39: V2-001 | C39: Amazon Prime Video | D39: V2 | E39: V1 · V3 | F39: Plataforma streaming | G39: Tier 2 | H39: EUA | I39: Ciudad de México | J39: Controla audiencia | K39: Fútbol | L39: Primer OTT global con acuerdo exclusivo de un club Liga MX. También firmó triple deal de patrocinio (Tri + Liga MX + Liga MX Femenil) desde mar-2025 vía Amazon/AWS. NBA y NFL TNF en Prime Video México. | M39: El acuerdo Chivas-Amazon reescribió el modelo de broadcasting local y fijó un benchmark que presiona al alza todos los contratos club-por-club. El triple deal de patrocinio inauguró la era del tech-as-sponsor en el ecosistema. | N39: Segunda plataforma de streaming mas grande en el mundo. | Q39: primevideo.com | R39: Verificado | S39: https://www.aboutamazon.mx/noticias/entretenimiento/amazon-prime-chivas-guadalajara | T39: =IF(G39="","",IF(OR(G39="Tier 3"),"No",IF(AND(S39<>"",OR(ISNUMBER(SEARCH("OFAC",S39)),ISNUMBER(SEARCH("penal",S39)),ISNUMBER(SEARCH("rojo pendiente",S39)))),"Revisar","Sí"))) -> Sí
